train_cls.py:37: YAMLLoadWarning: calling yaml.load() without Loader=... is deprecated, as the default Loader is unsafe. Please read https://msg.pyyaml.org/load for full details.
  config = yaml.load(f)

**************************

[workers]: 4

[num_points]: 1024

[num_classes]: 40

[batch_size]: 32

[base_lr]: 0.001

[lr_clip]: 1e-05

[lr_decay]: 0.7

[decay_step]: 21

[epochs]: 120

[weight_decay]: 1e-05

[bn_momentum]: 0.9

[bnm_clip]: 0.01

[bn_decay]: 0.5

[evaluate]: 1

[val_freq_epoch]: 1

[print_freq_iter]: 40

[input_channels]: 0

[relation_prior]: 1

[checkpoint]: 

[save_path]: cls

[data_root]: /media/disk3/pyy/RSCNN_Pytorch1.0/

**************************

/media/disk3/pyy/RSCNN_Pytorch1.0/data/ModelNet40Loader.py:14: H5pyDeprecationWarning: The default file mode will change to 'r' (read-only) in h5py 3.0. To suppress this warning, pass the mode you need to h5py.File(), or set the global default h5.get_config().default_file_mode, or set the environment variable H5PY_DEFAULT_READONLY=1. Available modes are: 'r', 'r+', 'w', 'w-'/'x', 'a'. See the docs for details.
  f = h5py.File(name)
Traceback (most recent call last):
  File "/home/s/anaconda2/envs/t1/lib/python3.6/site-packages/h5py/_hl/files.py", line 199, in make_fid
    fid = h5f.open(name, h5f.ACC_RDWR, fapl=fapl)
  File "h5py/_objects.pyx", line 54, in h5py._objects.with_phil.wrapper
  File "h5py/_objects.pyx", line 55, in h5py._objects.with_phil.wrapper
  File "h5py/h5f.pyx", line 88, in h5py.h5f.open
OSError: Unable to open file (unable to open file: name = '/media/disk3/pyy/RSCNN_Pytorch1.0/data/modelnet40_ply_hdf5_2048/ply_data_train0.h5', errno = 2, error message = 'No such file or directory', flags = 1, o_flags = 2)

During handling of the above exception, another exception occurred:

Traceback (most recent call last):
  File "/home/s/anaconda2/envs/t1/lib/python3.6/site-packages/h5py/_hl/files.py", line 202, in make_fid
    fid = h5f.open(name, h5f.ACC_RDONLY, fapl=fapl)
  File "h5py/_objects.pyx", line 54, in h5py._objects.with_phil.wrapper
  File "h5py/_objects.pyx", line 55, in h5py._objects.with_phil.wrapper
  File "h5py/h5f.pyx", line 88, in h5py.h5f.open
OSError: Unable to open file (unable to open file: name = '/media/disk3/pyy/RSCNN_Pytorch1.0/data/modelnet40_ply_hdf5_2048/ply_data_train0.h5', errno = 2, error message = 'No such file or directory', flags = 0, o_flags = 0)

During handling of the above exception, another exception occurred:

Traceback (most recent call last):
  File "train_cls.py", line 183, in <module>
    main()
  File "train_cls.py", line 59, in main
    train_dataset = ModelNet40Cls(num_points = args.num_points, root = args.data_root, transforms=train_transforms)
  File "/media/disk3/pyy/RSCNN_Pytorch1.0/data/ModelNet40Loader.py", line 51, in __init__
    points, labels = _load_data_file(os.path.join(root, f))
  File "/media/disk3/pyy/RSCNN_Pytorch1.0/data/ModelNet40Loader.py", line 14, in _load_data_file
    f = h5py.File(name)
  File "/home/s/anaconda2/envs/t1/lib/python3.6/site-packages/h5py/_hl/files.py", line 408, in __init__
    swmr=swmr)
  File "/home/s/anaconda2/envs/t1/lib/python3.6/site-packages/h5py/_hl/files.py", line 204, in make_fid
    fid = h5f.create(name, h5f.ACC_EXCL, fapl=fapl, fcpl=fcpl)
  File "h5py/_objects.pyx", line 54, in h5py._objects.with_phil.wrapper
  File "h5py/_objects.pyx", line 55, in h5py._objects.with_phil.wrapper
  File "h5py/h5f.pyx", line 108, in h5py.h5f.create
OSError: Unable to create file (unable to open file: name = '/media/disk3/pyy/RSCNN_Pytorch1.0/data/modelnet40_ply_hdf5_2048/ply_data_train0.h5', errno = 2, error message = 'No such file or directory', flags = 15, o_flags = c2)
